Workbook

Sheet README
A1: Acoustic sanity check (Verify first, item 1)
A2: Source: Handoff v2, outdoor party spot finder, 2026-10-12. Sound system filter: hardware class (typical playing level) x sound character.
A4: What it shows
A5: - Per class and character: octave-band level at 0.5, 1, 2, 3, 5 and 10 km (distances editable), spreading and air absorption only.
A6: - Whether the night target and the inaudible tier pass at those distances (Summary).
A7: - Rig-independent limits: the highest level at 1 m that still passes at each distance (Attenuation).
A9: How it is built
A10: - Class: a typical playing level, LAeq at a distance from the stack. Character: the spectrum shape. The character's bands are shifted so its dB(A) equals the class level.
A11: - Level at distance d = level at the class distance - 20 log10(d / class distance) - air absorption (dB/km) x (d - class distance).
A12: - Point source, free field, on axis. Air absorption per ISO 9613-1 at exact band centre frequencies.
A14: How to use
A15: 1. Inputs: yellow cells hold the defaults; change any of them, or enter a measured level in the Custom row.
... A40: - DIN 15905-5 summary (Barclays Arena sheet): https://www.barclays-arena.de/assets/doc/Merkblatt_Lautstrkemessung_DT_ENG-67c6f38df2.pdf

Sheet Inputs
A1: Inputs
A2: Edit the yellow cells. Everything else recalculates.
A4: Weather (air absorption)
A5: Air temperature (C) | B5: 10 | C5: [assumed: 10 C] Set to a typical night temperature for the event season.
A6: Relative humidity (%) | B6: 70 | C6: [assumed: 70 %]
A7: Air pressure (kPa) | B7: 101.325 | C7: Standard atmosphere.
A9: Night target at the receptor
A10: Night limit, dB(A) | B10: 40 | C10: NV 272/2011: base 50 dB, night -10 dB, LAeq,1h of the loudest hour, up to 2 m from the facade. Since Dec 2015 not applicable to outdoor music (Act 258/2000, s. 30(2)); kept as a reference.
A11: Music penalty, dB | B11: 5 | C11: NV 272/2011: -5 dB for tonal noise; music always counts as tonal.
A12: Night target used, dB(A) | B12: =B10-B11 -> 35
A14: Distance to receptor (km)
A15: 0.5 | B15: From handoff, Verify first item 1.
A16: 1
A17: 2
A18: 3
A19: 5
A20: 10
A22: Hardware class: typical playing level
A23: Class | B23: Playing level, LAeq dB(A) | C23: At distance from the stack (m) | D23: Source / status
A24: Small PA | B24: 99 | C24: 10 | D24: [assumed] Based on the German DIN 15905-5 audience limit of 99 dB(A) LAeq,30min and a 99.6 dB(A) mean measured at concert mix positions (Griffiths & Staunton, IOA). Not measured at outdoor parties. Distance [assumed: 10 m].
A25: Medium (2-4 subs) | B25: 99 | C25: 20 | D25: [assumed] Based on the German DIN 15905-5 audience limit of 99 dB(A) LAeq,30min and a 99.6 dB(A) mean measured at concert mix positions (Griffiths & Staunton, IOA). Not measured at outdoor parties. Distance [assumed: 20 m].
A26: Large | B26: 99 | C26: 40 | D26: [assumed] Based on the German DIN 15905-5 audience limit of 99 dB(A) LAeq,30min and a 99.6 dB(A) mean measured at concert mix positions (Griffiths & Staunton, IOA). Not measured at outdoor parties. Distance [assumed: 40 m]. IOA paper: mix positions 15 m (small venues) to 50 m (stadia).
A27: Custom (measured) | D27: Optional: a measured LAeq and the distance it was measured at.
A29: Sound character: octave-band spectrum shape, dB unweighted (scaled to the class level)
A30: Character | B30: 31.5 Hz | C30: 63 Hz | D30: 125 Hz | E30: 250 Hz | F30: 500 Hz | G30: 1 kHz | H30: 2 kHz | I30: 4 kHz | J30: 8 kHz | K30: dB(A) of row | L30: dB(C) of row | M30: Source
A31: Balanced | B31: 99 | C31: 109 | D31: 100 | E31: 97 | F31: 97 | G31: 92 | H31: 88 | I31: 84 | J31: 78 | K31: =10*LOG10(SUMPRODUCT(10^((B31:J31+Reference!$B$7:$J$7)/10))) -> 97.999919 | L31: =10*LOG10(SUMPRODUCT(10^((B31:J31+Reference!$B$8:$J$8)/10))) -> 109.64034 | M31: Source genre: Alt & Rock. Chosen over Pop (same dB(C) minus dB(A)) because it gives the lower margin at every class and distance.
A32: Bass heavy | B32: 109 | C32: 113 | D32: 98 | E32: 96 | F32: 94 | G32: 94 | H32: 90 | I32: 86 | J32: 84 | K32: =10*LOG10(SUMPRODUCT(10^((B32:J32+Reference!$B$7:$J$7)/10))) -> 98.401533 | L32: =10*LOG10(SUMPRODUCT(10^((B32:J32+Reference!$B$8:$J$8)/10))) -> 113.46767 | M32: Source genre: Urban.
A33: Very bass heavy | B33: 111 | C33: 116 | D33: 101 | E33: 96 | F33: 94 | G33: 93 | H33: 89 | I33: 85 | J33: 83 | K33: =10*LOG10(SUMPRODUCT(10^((B33:J33+Reference!$B$7:$J$7)/10))) -> 98.212292 | L33: =10*LOG10(SUMPRODUCT(10^((B33:J33+Reference!$B$8:$J$8)/10))) -> 116.18946 | M33: Source genre: Dance. Strongest 31.5 and 63 Hz.
A35: Character spectra: Fiumicelli, Parker, Lawrence, Stewart, Low frequency sound at outdoor concerts: a necessary noise (IOA), Table 1. Octave bands normalised to 98 dB(A).
A36: Classes need both cells filled; an empty class leaves its rows blank in Results and Summary.

Sheet Summary
A1: Summary
A2: Green passes, red fails. Blank: the class has no level entered.
A4: Margin to night target, dB(A)
A5: Class | B5: Character | C5: =Inputs!A15 -> 0.5 | D5: =Inputs!A16 -> 1 | E5: =Inputs!A17 -> 2 | F5: =Inputs!A18 -> 3 | G5: =Inputs!A19 -> 5 | H5: =Inputs!A20 -> 10
A6: =Inputs!A24 -> Small PA | B6: =Inputs!A31 -> Balanced | C6: =IF(Results!M7="","",Results!M7) -> -28.359902 | D6: =IF(Results!M8="","",Results!M8) -> -21.160743 | E6: =IF(Results!M9="","",Results!M9) -> -13.225393 | F6: =IF(Results!M10="","",Results!M10) -> -8.1112941 | G6: =IF(Results!M11="","",Results!M11) -> -1.1258694 | H6: =IF(Results!M12="","",Results!M12) -> 8.7910166
A7: =Inputs!A24 -> Small PA | B7: =Inputs!A32 -> Bass heavy | C7: =IF(Results!M25="","",Results!M25) -> -27.854497 | D7: =IF(Results!M26="","",Results!M26) -> -20.456585 | E7: =IF(Results!M27="","",Results!M27) -> -12.395959 | F7: =IF(Results!M28="","",Results!M28) -> -7.3810117 | G7: =IF(Results!M29="","",Results!M29) -> -0.94420105 | H7: =IF(Results!M30="","",Results!M30) -> 7.454692
A8: =Inputs!A24 -> Small PA | B8: =Inputs!A33 -> Very bass heavy | C8: =IF(Results!M43="","",Results!M43) -> -28.232525 | D8: =IF(Results!M44="","",Results!M44) -> -21.121859 | E8: =IF(Results!M45="","",Results!M45) -> -13.563756 | F8: =IF(Results!M46="","",Results!M46) -> -8.9734618 | G8: =IF(Results!M47="","",Results!M47) -> -3.1558985 | H8: =IF(Results!M48="","",Results!M48) -> 4.5749683
A9: =Inputs!A25 -> Medium (2-4 subs) | B9: =Inputs!A31 -> Balanced | C9: =IF(Results!M61="","",Results!M61) -> -34.406773 | D9: =IF(Results!M62="","",Results!M62) -> -27.202938 | E9: =IF(Results!M63="","",Results!M63) -> -19.263273 | F9: =IF(Results!M64="","",Results!M64) -> -14.14662 | G9: =IF(Results!M65="","",Results!M65) -> -7.1574424 | H9: =IF(Results!M66="","",Results!M66) -> 2.7650377
A10: =Inputs!A25 -> Medium (2-4 subs) | B10: =Inputs!A32 -> Bass heavy | C10: =IF(Results!M79="","",Results!M79) -> -33.906763 | D10: =IF(Results!M80="","",Results!M80) -> -26.501638 | E10: =IF(Results!M81="","",Results!M81) -> -18.433795 | F10: =IF(Results!M82="","",Results!M82) -> -13.41455 | G10: =IF(Results!M83="","",Results!M83) -> -6.9724509 | H10: =IF(Results!M84="","",Results!M84) -> 1.431049
A11: =Inputs!A25 -> Medium (2-4 subs) | B11: =Inputs!A33 -> Very bass heavy | C11: =IF(Results!M97="","",Results!M97) -> -34.278659 | D11: =IF(Results!M98="","",Results!M98) -> -27.161451 | E11: =IF(Results!M99="","",Results!M99) -> -19.596959 | F11: =IF(Results!M100="","",Results!M100) -> -15.003138 | G11: =IF(Results!M101="","",Results!M101) -> -9.1817536 | H11: =IF(Results!M102="","",Results!M102) -> -1.4480106
A12: =Inputs!A26 -> Large | B12: =Inputs!A31 -> Balanced | C12: =IF(Results!M115="","",Results!M115) -> -40.480361 | D12: =IF(Results!M116="","",Results!M116) -> -33.266921 | E12: =IF(Results!M117="","",Results!M117) -> -25.318525 | F12: =IF(Results!M118="","",Results!M118) -> -20.196738 | G12: =IF(Results!M119="","",Results!M119) -> -13.200037 | H12: =IF(Results!M120="","",Results!M120) -> -3.2663411
A13: =Inputs!A26 -> Large | B13: =Inputs!A32 -> Bass heavy | C13: =IF(Results!M133="","",Results!M133) -> -39.991361 | D13: =IF(Results!M134="","",Results!M134) -> -32.571456 | E13: =IF(Results!M135="","",Results!M135) -> -24.489025 | F13: =IF(Results!M136="","",Results!M136) -> -19.461136 | G13: =IF(Results!M137="","",Results!M137) -> -13.008407 | H13: =IF(Results!M138="","",Results!M138) -> -4.595649
A14: =Inputs!A26 -> Large | B14: =Inputs!A33 -> Very bass heavy | C14: =IF(Results!M151="","",Results!M151) -> -40.350928 | D14: =IF(Results!M152="","",Results!M152) -> -33.220319 | E14: =IF(Results!M153="","",Results!M153) -> -25.6429 | F14: =IF(Results!M154="","",Results!M154) -> -21.041976 | G14: =IF(Results!M155="","",Results!M155) -> -15.212901 | H14: =IF(Results!M156="","",Results!M156) -> -7.4733755
A15: =Inputs!A27 -> Custom (measured) | B15: =Inputs!A31 -> Balanced | C15: =IF(Results!M169="","",Results!M169) | D15: =IF(Results!M170="","",Results!M170) | E15: =IF(Results!M171="","",Results!M171) | F15: =IF(Results!M172="","",Results!M172) | G15: =IF(Results!M173="","",Results!M173) | H15: =IF(Results!M174="","",Results!M174)
A16: =Inputs!A27 -> Custom (measured) | B16: =Inputs!A32 -> Bass heavy | C16: =IF(Results!M187="","",Results!M187) | D16: =IF(Results!M188="","",Results!M188) | E16: =IF(Results!M189="","",Results!M189) | F16: =IF(Results!M190="","",Results!M190) | G16: =IF(Results!M191="","",Results!M191) | H16: =IF(Results!M192="","",Results!M192)
A17: =Inputs!A27 -> Custom (measured) | B17: =Inputs!A33 -> Very bass heavy | C17: =IF(Results!M205="","",Results!M205) | D17: =IF(Results!M206="","",Results!M206) | E17: =IF(Results!M207="","",Results!M207) | F17: =IF(Results!M208="","",Results!M208) | G17: =IF(Results!M209="","",Results!M209) | H17: =IF(Results!M210="","",Results!M210)
A20: Worst band margin to hearing threshold, dB
A21: Class | B21: Character | C21: =Inputs!A15 -> 0.5 | D21: =Inputs!A16 -> 1 | E21: =Inputs!A17 -> 2 | F21: =Inputs!A18 -> 3 | G21: =Inputs!A19 -> 5 | H21: =Inputs!A20 -> 10
A22: =Inputs!A24 -> Small PA | B22: =Inputs!A31 -> Balanced | C22: =IF(Results!K15="","",Results!K15) -> -58.676029 | D22: =IF(Results!K16="","",Results!K16) -> -51.691498 | E22: =IF(Results!K17="","",Results!K17) -> -43.743036 | F22: =IF(Results!K18="","",Results!K18) -> -38.293348 | G22: =IF(Results!K19="","",Results!K19) -> -30.000649 | H22: =IF(Results!K20="","",Results!K20) -> -16.176841
A23: =Inputs!A24 -> Small PA | B23: =Inputs!A32 -> Bass heavy | C23: =IF(Results!K33="","",Results!K33) -> -56.426801 | D23: =IF(Results!K34="","",Results!K34) -> -48.577358 | E23: =IF(Results!K35="","",Results!K35) -> -40.341422 | F23: =IF(Results!K36="","",Results!K36) -> -34.891734 | G23: =IF(Results!K37="","",Results!K37) -> -26.599035 | H23: =IF(Results!K38="","",Results!K38) -> -14.88279
A24: =Inputs!A24 -> Small PA | B24: =Inputs!A33 -> Very bass heavy | C24: =IF(Results!K51="","",Results!K51) -> -55.616041 | D24: =IF(Results!K52="","",Results!K52) -> -48.479124 | E24: =IF(Results!K53="","",Results!K53) -> -40.530662 | F24: =IF(Results!K54="","",Results!K54) -> -35.080975 | G24: =IF(Results!K55="","",Results!K55) -> -26.788276 | H24: =IF(Results!K56="","",Results!K56) -> -18.07203
A25: =Inputs!A25 -> Medium (2-4 subs) | B25: =Inputs!A31 -> Balanced | C25: =IF(Results!K69="","",Results!K69) -> -64.715907 | D25: =IF(Results!K70="","",Results!K70) -> -57.731376 | E25: =IF(Results!K71="","",Results!K71) -> -49.782914 | F25: =IF(Results!K72="","",Results!K72) -> -44.333227 | G25: =IF(Results!K73="","",Results!K73) -> -36.040528 | H25: =IF(Results!K74="","",Results!K74) -> -22.207875
A26: =Inputs!A25 -> Medium (2-4 subs) | B26: =Inputs!A32 -> Bass heavy | C26: =IF(Results!K87="","",Results!K87) -> -62.483978 | D26: =IF(Results!K88="","",Results!K88) -> -54.634535 | E26: =IF(Results!K89="","",Results!K89) -> -46.3813 | F26: =IF(Results!K90="","",Results!K90) -> -40.931613 | G26: =IF(Results!K91="","",Results!K91) -> -32.638914 | H26: =IF(Results!K92="","",Results!K92) -> -20.904607
A27: =Inputs!A25 -> Medium (2-4 subs) | B27: =Inputs!A33 -> Very bass heavy | C27: =IF(Results!K105="","",Results!K105) -> -61.673218 | D27: =IF(Results!K106="","",Results!K106) -> -54.519003 | E27: =IF(Results!K107="","",Results!K107) -> -46.570541 | F27: =IF(Results!K108="","",Results!K108) -> -41.120853 | G27: =IF(Results!K109="","",Results!K109) -> -32.828154 | H27: =IF(Results!K110="","",Results!K110) -> -24.093847
A28: =Inputs!A26 -> Large | B28: =Inputs!A31 -> Balanced | C28: =IF(Results!K123="","",Results!K123) -> -70.775064 | D28: =IF(Results!K124="","",Results!K124) -> -63.790533 | E28: =IF(Results!K125="","",Results!K125) -> -55.842071 | F28: =IF(Results!K126="","",Results!K126) -> -50.392384 | G28: =IF(Results!K127="","",Results!K127) -> -42.099685 | H28: =IF(Results!K128="","",Results!K128) -> -28.249342
A29: =Inputs!A26 -> Large | B29: =Inputs!A32 -> Bass heavy | C29: =IF(Results!K141="","",Results!K141) -> -68.577731 | D29: =IF(Results!K142="","",Results!K142) -> -60.728289 | E29: =IF(Results!K143="","",Results!K143) -> -52.440457 | F29: =IF(Results!K144="","",Results!K144) -> -46.99077 | G29: =IF(Results!K145="","",Results!K145) -> -38.698071 | H29: =IF(Results!K146="","",Results!K146) -> -26.92764
A30: =Inputs!A26 -> Large | B30: =Inputs!A33 -> Very bass heavy | C30: =IF(Results!K159="","",Results!K159) -> -67.766972 | D30: =IF(Results!K160="","",Results!K160) -> -60.57816 | E30: =IF(Results!K161="","",Results!K161) -> -52.629698 | F30: =IF(Results!K162="","",Results!K162) -> -47.18001 | G30: =IF(Results!K163="","",Results!K163) -> -38.887311 | H30: =IF(Results!K164="","",Results!K164) -> -30.116881
A31: =Inputs!A27 -> Custom (measured) | B31: =Inputs!A31 -> Balanced | C31: =IF(Results!K177="","",Results!K177) | D31: =IF(Results!K178="","",Results!K178) | E31: =IF(Results!K179="","",Results!K179) | F31: =IF(Results!K180="","",Results!K180) | G31: =IF(Results!K181="","",Results!K181) | H31: =IF(Results!K182="","",Results!K182)
A32: =Inputs!A27 -> Custom (measured) | B32: =Inputs!A32 -> Bass heavy | C32: =IF(Results!K195="","",Results!K195) | D32: =IF(Results!K196="","",Results!K196) | E32: =IF(Results!K197="","",Results!K197) | F32: =IF(Results!K198="","",Results!K198) | G32: =IF(Results!K199="","",Results!K199) | H32: =IF(Results!K200="","",Results!K200)
A33: =Inputs!A27 -> Custom (measured) | B33: =Inputs!A33 -> Very bass heavy | C33: =IF(Results!K213="","",Results!K213) | D33: =IF(Results!K214="","",Results!K214) | E33: =IF(Results!K215="","",Results!K215) | F33: =IF(Results!K216="","",Results!K216) | G33: =IF(Results!K217="","",Results!K217) | H33: =IF(Results!K218="","",Results!K218)
A36: Inaudible in all bands?
A37: Class | B37: Character | C37: =Inputs!A15 -> 0.5 | D37: =Inputs!A16 -> 1 | E37: =Inputs!A17 -> 2 | F37: =Inputs!A18 -> 3 | G37: =Inputs!A19 -> 5 | H37: =Inputs!A20 -> 10
A38: =Inputs!A24 -> Small PA | B38: =Inputs!A31 -> Balanced | C38: =IF(Results!L15="","",Results!L15) -> no | D38: =IF(Results!L16="","",Results!L16) -> no | E38: =IF(Results!L17="","",Results!L17) -> no | F38: =IF(Results!L18="","",Results!L18) -> no | G38: =IF(Results!L19="","",Results!L19) -> no | H38: =IF(Results!L20="","",Results!L20) -> no
A39: =Inputs!A24 -> Small PA | B39: =Inputs!A32 -> Bass heavy | C39: =IF(Results!L33="","",Results!L33) -> no | D39: =IF(Results!L34="","",Results!L34) -> no | E39: =IF(Results!L35="","",Results!L35) -> no | F39: =IF(Results!L36="","",Results!L36) -> no | G39: =IF(Results!L37="","",Results!L37) -> no | H39: =IF(Results!L38="","",Results!L38) -> no
A40: =Inputs!A24 -> Small PA | B40: =Inputs!A33 -> Very bass heavy | C40: =IF(Results!L51="","",Results!L51) -> no | D40: =IF(Results!L52="","",Results!L52) -> no | E40: =IF(Results!L53="","",Results!L53) -> no | F40: =IF(Results!L54="","",Results!L54) -> no | G40: =IF(Results!L55="","",Results!L55) -> no | H40: =IF(Results!L56="","",Results!L56) -> no
A41: =Inputs!A25 -> Medium (2-4 subs) | B41: =Inputs!A31 -> Balanced | C41: =IF(Results!L69="","",Results!L69) -> no | D41: =IF(Results!L70="","",Results!L70) -> no | E41: =IF(Results!L71="","",Results!L71) -> no | F41: =IF(Results!L72="","",Results!L72) -> no | G41: =IF(Results!L73="","",Results!L73) -> no | H41: =IF(Results!L74="","",Results!L74) -> no
A42: =Inputs!A25 -> Medium (2-4 subs) | B42: =Inputs!A32 -> Bass heavy | C42: =IF(Results!L87="","",Results!L87) -> no | D42: =IF(Results!L88="","",Results!L88) -> no | E42: =IF(Results!L89="","",Results!L89) -> no | F42: =IF(Results!L90="","",Results!L90) -> no | G42: =IF(Results!L91="","",Results!L91) -> no | H42: =IF(Results!L92="","",Results!L92) -> no
A43: =Inputs!A25 -> Medium (2-4 subs) | B43: =Inputs!A33 -> Very bass heavy | C43: =IF(Results!L105="","",Results!L105) -> no | D43: =IF(Results!L106="","",Results!L106) -> no | E43: =IF(Results!L107="","",Results!L107) -> no | F43: =IF(Results!L108="","",Results!L108) -> no | G43: =IF(Results!L109="","",Results!L109) -> no | H43: =IF(Results!L110="","",Results!L110) -> no
A44: =Inputs!A26 -> Large | B44: =Inputs!A31 -> Balanced | C44: =IF(Results!L123="","",Results!L123) -> no | D44: =IF(Results!L124="","",Results!L124) -> no | E44: =IF(Results!L125="","",Results!L125) -> no | F44: =IF(Results!L126="","",Results!L126) -> no | G44: =IF(Results!L127="","",Results!L127) -> no | H44: =IF(Results!L128="","",Results!L128) -> no
A45: =Inputs!A26 -> Large | B45: =Inputs!A32 -> Bass heavy | C45: =IF(Results!L141="","",Results!L141) -> no | D45: =IF(Results!L142="","",Results!L142) -> no | E45: =IF(Results!L143="","",Results!L143) -> no | F45: =IF(Results!L144="","",Results!L144) -> no | G45: =IF(Results!L145="","",Results!L145) -> no | H45: =IF(Results!L146="","",Results!L146) -> no
...

Sheet Reference
A1: Reference values per octave band
A3: Row | B3: 31.5 Hz | C3: 63 Hz | D3: 125 Hz | E3: 250 Hz | F3: 500 Hz | G3: 1 kHz | H3: 2 kHz | I3: 4 kHz | J3: 8 kHz | K3: Source
A4: Nominal frequency (Hz) | B4: 31.5 | C4: 63 | D4: 125 | E4: 250 | F4: 500 | G4: 1000 | H4: 2000 | I4: 4000 | J4: 8000 | K4: ISO 266 preferred frequencies.
A5: Band index k | B5: -5 | C5: -4 | D5: -3 | E5: -2 | F5: -1 | G5: 0 | H5: 1 | I5: 2 | J5: 3 | K5: Exact centre = 1000 x 10^(0.3 k).
A6: Exact centre frequency (Hz) | B6: =1000*10^(0.3*B5) -> 31.622777 | C6: =1000*10^(0.3*C5) -> 63.095734 | D6: =1000*10^(0.3*D5) -> 125.89254 | E6: =1000*10^(0.3*E5) -> 251.18864 | F6: =1000*10^(0.3*F5) -> 501.18723 | G6: =1000*10^(0.3*G5) -> 1000 | H6: =1000*10^(0.3*H5) -> 1995.2623 | I6: =1000*10^(0.3*I5) -> 3981.0717 | J6: =1000*10^(0.3*J5) -> 7943.2823 | K6: Used for air absorption.
A7: A-weighting (dB) | B7: -39.4 | C7: -26.2 | D7: -16.1 | E7: -8.6 | F7: -3.2 | G7: 0 | H7: 1.2 | I7: 1 | J7: -1.1 | K7: IEC 61672-1.
A8: C-weighting (dB) | B8: -3 | C8: -0.8 | D8: -0.2 | E8: 0 | F8: 0 | G8: 0 | H8: -0.2 | I8: -0.8 | J8: -3 | K8: IEC 61672-1.
A9: Hearing threshold (dB) | B9: 59.5 | C9: 37.5 | D9: 22.1 | E9: 11.4 | F9: 4.4 | G9: 2.4 | H9: -1.3 | I9: -5.4 | J9: 12.6 | K9: [unverified] Recalled ISO 226:2003 threshold, pure tones, free field, binaural. Applied to octave bands as an approximation.
A10: Air absorption (dB/km) | B10: =1000*8.686*B6^2*(0.0000000000184/$B$15*($B$14/293.15)^0.5+($B$14/293.15)^(-2.5)*(0.01275*EXP(-2239.1/$B$14)/($B$18+B6^2/$B$18)+0.1068*EXP(-3352/$B$14)/($B$19+B6^2/$B$19))) -> 0.032028999 | C10: =1000*8.686*C6^2*(0.0000000000184/$B$15*($B$14/293.15)^0.5+($B$14/293.15)^(-2.5)*(0.01275*EXP(-2239.1/$B$14)/($B$18+C6^2/$B$18)+0.1068*EXP(-3352/$B$14)/($B$19+C6^2/$B$19))) -> 0.1216894 | D10: =1000*8.686*D6^2*(0.0000000000184/$B$15*($B$14/293.15)^0.5+($B$14/293.15)^(-2.5)*(0.01275*EXP(-2239.1/$B$14)/($B$18+D6^2/$B$18)+0.1068*EXP(-3352/$B$14)/($B$19+D6^2/$B$19))) -> 0.41095027 | E10: =1000*8.686*E6^2*(0.0000000000184/$B$15*($B$14/293.15)^0.5+($B$14/293.15)^(-2.5)*(0.01275*EXP(-2239.1/$B$14)/($B$18+E6^2/$B$18)+0.1068*EXP(-3352/$B$14)/($B$19+E6^2/$B$19))) -> 1.0433673 | F10: =1000*8.686*F6^2*(0.0000000000184/$B$15*($B$14/293.15)^0.5+($B$14/293.15)^(-2.5)*(0.01275*EXP(-2239.1/$B$14)/($B$18+F6^2/$B$18)+0.1068*EXP(-3352/$B$14)/($B$19+F6^2/$B$19))) -> 1.9278621 | G10: =1000*8.686*G6^2*(0.0000000000184/$B$15*($B$14/293.15)^0.5+($B$14/293.15)^(-2.5)*(0.01275*EXP(-2239.1/$B$14)/($B$18+G6^2/$B$18)+0.1068*EXP(-3352/$B$14)/($B$19+G6^2/$B$19))) -> 3.6576857 | H10: =1000*8.686*H6^2*(0.0000000000184/$B$15*($B$14/293.15)^0.5+($B$14/293.15)^(-2.5)*(0.01275*EXP(-2239.1/$B$14)/($B$18+H6^2/$B$18)+0.1068*EXP(-3352/$B$14)/($B$19+H6^2/$B$19))) -> 9.6639454 | I10: =1000*8.686*I6^2*(0.0000000000184/$B$15*($B$14/293.15)^0.5+($B$14/293.15)^(-2.5)*(0.01275*EXP(-2239.1/$B$14)/($B$18+I6^2/$B$18)+0.1068*EXP(-3352/$B$14)/($B$19+I6^2/$B$19))) -> 32.77013 | J10: =1000*8.686*J6^2*(0.0000000000184/$B$15*($B$14/293.15)^0.5+($B$14/293.15)^(-2.5)*(0.01275*EXP(-2239.1/$B$14)/($B$18+J6^2/$B$18)+0.1068*EXP(-3352/$B$14)/($B$19+J6^2/$B$19))) -> 116.88204 | K10: ISO 9613-1 formula, weather from Inputs.
A13: Air absorption intermediates (ISO 9613-1)
A14: Temperature (K) | B14: =Inputs!B5+273.15 -> 283.15
A15: Pressure ratio pa/pr | B15: =Inputs!B7/101.325 -> 1
A16: Exponent C | B16: =-6.8346*(273.16/B14)^1.261+4.6151 -> -1.9168399
A17: Water vapour h (%) | B17: =Inputs!B6*10^B16/B15 -> 0.84773113
A18: Oxygen relaxation frO (Hz) | B18: =B15*(24+40400*B17*(0.02+B17)/(0.391+B17)) -> 24014.96
A19: Nitrogen relaxation frN (Hz) | B19: =B15*(B14/293.15)^(-0.5)*(9+280*B17*EXP(-4.17*((B14/293.15)^(-1/3)-1))) -> 239.23774

Sheet Attenuation
A1: Rig-independent figures
A2: Same for every class and character. Reference distance 1 m.
A4: Attenuation from 1 m (dB): spreading + air absorption
A5: Distance (km) | B5: 31.5 Hz | C5: 63 Hz | D5: 125 Hz | E5: 250 Hz | F5: 500 Hz | G5: 1 kHz | H5: 2 kHz | I5: 4 kHz | J5: 8 kHz
A6: =Inputs!A15 -> 0.5 | B6: =20*LOG10($A6*1000)+Reference!B$10*($A6*1000-1)/1000 -> 53.995383 | C6: =20*LOG10($A6*1000)+Reference!C$10*($A6*1000-1)/1000 -> 54.040123 | D6: =20*LOG10($A6*1000)+Reference!D$10*($A6*1000-1)/1000 -> 54.184464 | E6: =20*LOG10($A6*1000)+Reference!E$10*($A6*1000-1)/1000 -> 54.50004 | F6: =20*LOG10($A6*1000)+Reference!F$10*($A6*1000-1)/1000 -> 54.941403 | G6: =20*LOG10($A6*1000)+Reference!G$10*($A6*1000-1)/1000 -> 55.804585 | H6: =20*LOG10($A6*1000)+Reference!H$10*($A6*1000-1)/1000 -> 58.801709 | I6: =20*LOG10($A6*1000)+Reference!I$10*($A6*1000-1)/1000 -> 70.331695 | J6: =20*LOG10($A6*1000)+Reference!J$10*($A6*1000-1)/1000 -> 112.30354
A7: =Inputs!A16 -> 1 | B7: =20*LOG10($A7*1000)+Reference!B$10*($A7*1000-1)/1000 -> 60.031997 | C7: =20*LOG10($A7*1000)+Reference!C$10*($A7*1000-1)/1000 -> 60.121568 | D7: =20*LOG10($A7*1000)+Reference!D$10*($A7*1000-1)/1000 -> 60.410539 | E7: =20*LOG10($A7*1000)+Reference!E$10*($A7*1000-1)/1000 -> 61.042324 | F7: =20*LOG10($A7*1000)+Reference!F$10*($A7*1000-1)/1000 -> 61.925934 | G7: =20*LOG10($A7*1000)+Reference!G$10*($A7*1000-1)/1000 -> 63.654028 | H7: =20*LOG10($A7*1000)+Reference!H$10*($A7*1000-1)/1000 -> 69.654281 | I7: =20*LOG10($A7*1000)+Reference!I$10*($A7*1000-1)/1000 -> 92.737359 | J7: =20*LOG10($A7*1000)+Reference!J$10*($A7*1000-1)/1000 -> 176.76516
A8: =Inputs!A17 -> 2 | B8: =20*LOG10($A8*1000)+Reference!B$10*($A8*1000-1)/1000 -> 66.084626 | C8: =20*LOG10($A8*1000)+Reference!C$10*($A8*1000-1)/1000 -> 66.263857 | D8: =20*LOG10($A8*1000)+Reference!D$10*($A8*1000-1)/1000 -> 66.84209 | E8: =20*LOG10($A8*1000)+Reference!E$10*($A8*1000-1)/1000 -> 68.106291 | F8: =20*LOG10($A8*1000)+Reference!F$10*($A8*1000-1)/1000 -> 69.874396 | G8: =20*LOG10($A8*1000)+Reference!G$10*($A8*1000-1)/1000 -> 73.332314 | H8: =20*LOG10($A8*1000)+Reference!H$10*($A8*1000-1)/1000 -> 85.338827 | I8: =20*LOG10($A8*1000)+Reference!I$10*($A8*1000-1)/1000 -> 131.52809 | J8: =20*LOG10($A8*1000)+Reference!J$10*($A8*1000-1)/1000 -> 299.66781
A9: =Inputs!A18 -> 3 | B9: =20*LOG10($A9*1000)+Reference!B$10*($A9*1000-1)/1000 -> 69.63848 | C9: =20*LOG10($A9*1000)+Reference!C$10*($A9*1000-1)/1000 -> 69.907372 | D9: =20*LOG10($A9*1000)+Reference!D$10*($A9*1000-1)/1000 -> 70.774865 | E9: =20*LOG10($A9*1000)+Reference!E$10*($A9*1000-1)/1000 -> 72.671484 | F9: =20*LOG10($A9*1000)+Reference!F$10*($A9*1000-1)/1000 -> 75.324084 | G9: =20*LOG10($A9*1000)+Reference!G$10*($A9*1000-1)/1000 -> 80.511825 | H9: =20*LOG10($A9*1000)+Reference!H$10*($A9*1000-1)/1000 -> 98.524597 | I9: =20*LOG10($A9*1000)+Reference!I$10*($A9*1000-1)/1000 -> 167.82004 | J9: =20*LOG10($A9*1000)+Reference!J$10*($A9*1000-1)/1000 -> 420.07168
A10: =Inputs!A19 -> 5 | B10: =20*LOG10($A10*1000)+Reference!B$10*($A10*1000-1)/1000 -> 74.139513 | C10: =20*LOG10($A10*1000)+Reference!C$10*($A10*1000-1)/1000 -> 74.587725 | D10: =20*LOG10($A10*1000)+Reference!D$10*($A10*1000-1)/1000 -> 76.03374 | E10: =20*LOG10($A10*1000)+Reference!E$10*($A10*1000-1)/1000 -> 79.195193 | F10: =20*LOG10($A10*1000)+Reference!F$10*($A10*1000-1)/1000 -> 83.616783 | G10: =20*LOG10($A10*1000)+Reference!G$10*($A10*1000-1)/1000 -> 92.264171 | H10: =20*LOG10($A10*1000)+Reference!H$10*($A10*1000-1)/1000 -> 122.28946 | I10: =20*LOG10($A10*1000)+Reference!I$10*($A10*1000-1)/1000 -> 237.79728 | J10: =20*LOG10($A10*1000)+Reference!J$10*($A10*1000-1)/1000 -> 658.27274
A11: =Inputs!A20 -> 10 | B11: =20*LOG10($A11*1000)+Reference!B$10*($A11*1000-1)/1000 -> 80.320258 | C11: =20*LOG10($A11*1000)+Reference!C$10*($A11*1000-1)/1000 -> 81.216772 | D11: =20*LOG10($A11*1000)+Reference!D$10*($A11*1000-1)/1000 -> 84.109092 | E11: =20*LOG10($A11*1000)+Reference!E$10*($A11*1000-1)/1000 -> 90.43263 | F11: =20*LOG10($A11*1000)+Reference!F$10*($A11*1000-1)/1000 -> 99.276693 | G11: =20*LOG10($A11*1000)+Reference!G$10*($A11*1000-1)/1000 -> 116.5732 | H11: =20*LOG10($A11*1000)+Reference!H$10*($A11*1000-1)/1000 -> 176.62979 | I11: =20*LOG10($A11*1000)+Reference!I$10*($A11*1000-1)/1000 -> 407.66853 | J11: =20*LOG10($A11*1000)+Reference!J$10*($A11*1000-1)/1000 -> 1248.7036
A13: Inaudible tier: highest band level at 1 m that stays below the hearing threshold (dB)
A14: Distance (km) | B14: 31.5 Hz | C14: 63 Hz | D14: 125 Hz | E14: 250 Hz | F14: 500 Hz | G14: 1 kHz | H14: 2 kHz | I14: 4 kHz | J14: 8 kHz
A15: =A6 -> 0.5 | B15: =Reference!B$9+B6 -> 113.49538 | C15: =Reference!C$9+C6 -> 91.540123 | D15: =Reference!D$9+D6 -> 76.284464 | E15: =Reference!E$9+E6 -> 65.90004 | F15: =Reference!F$9+F6 -> 59.341403 | G15: =Reference!G$9+G6 -> 58.204585 | H15: =Reference!H$9+H6 -> 57.501709 | I15: =Reference!I$9+I6 -> 64.931695 | J15: =Reference!J$9+J6 -> 124.90354
A16: =A7 -> 1 | B16: =Reference!B$9+B7 -> 119.532 | C16: =Reference!C$9+C7 -> 97.621568 | D16: =Reference!D$9+D7 -> 82.510539 | E16: =Reference!E$9+E7 -> 72.442324 | F16: =Reference!F$9+F7 -> 66.325934 | G16: =Reference!G$9+G7 -> 66.054028 | H16: =Reference!H$9+H7 -> 68.354281 | I16: =Reference!I$9+I7 -> 87.337359 | J16: =Reference!J$9+J7 -> 189.36516
A17: =A8 -> 2 | B17: =Reference!B$9+B8 -> 125.58463 | C17: =Reference!C$9+C8 -> 103.76386 | D17: =Reference!D$9+D8 -> 88.94209 | E17: =Reference!E$9+E8 -> 79.506291 | F17: =Reference!F$9+F8 -> 74.274396 | G17: =Reference!G$9+G8 -> 75.732314 | H17: =Reference!H$9+H8 -> 84.038827 | I17: =Reference!I$9+I8 -> 126.12809 | J17: =Reference!J$9+J8 -> 312.26781
A18: =A9 -> 3 | B18: =Reference!B$9+B9 -> 129.13848 | C18: =Reference!C$9+C9 -> 107.40737 | D18: =Reference!D$9+D9 -> 92.874865 | E18: =Reference!E$9+E9 -> 84.071484 | F18: =Reference!F$9+F9 -> 79.724084 | G18: =Reference!G$9+G9 -> 82.911825 | H18: =Reference!H$9+H9 -> 97.224597 | I18: =Reference!I$9+I9 -> 162.42004 | J18: =Reference!J$9+J9 -> 432.67168
A19: =A10 -> 5 | B19: =Reference!B$9+B10 -> 133.63951 | C19: =Reference!C$9+C10 -> 112.08773 | D19: =Reference!D$9+D10 -> 98.13374 | E19: =Reference!E$9+E10 -> 90.595193 | F19: =Reference!F$9+F10 -> 88.016783 | G19: =Reference!G$9+G10 -> 94.664171 | H19: =Reference!H$9+H10 -> 120.98946 | I19: =Reference!I$9+I10 -> 232.39728 | J19: =Reference!J$9+J10 -> 670.87274
A20: =A11 -> 10 | B20: =Reference!B$9+B11 -> 139.82026 | C20: =Reference!C$9+C11 -> 118.71677 | D20: =Reference!D$9+D11 -> 106.20909 | E20: =Reference!E$9+E11 -> 101.83263 | F20: =Reference!F$9+F11 -> 103.67669 | G20: =Reference!G$9+G11 -> 118.9732 | H20: =Reference!H$9+H11 -> 175.32979 | I20: =Reference!I$9+I11 -> 402.26853 | J20: =Reference!J$9+J11 -> 1261.3036
A22: Night target: highest total dB(A) at 1 m, spreading only (air absorption ignored, so slightly strict)
A23: Distance (km) | B23: Max dB(A) at 1 m
A24: =A6 -> 0.5 | B24: =Inputs!$B$12+20*LOG10($A24*1000) -> 88.9794
A25: =A7 -> 1 | B25: =Inputs!$B$12+20*LOG10($A25*1000) -> 95
A26: =A8 -> 2 | B26: =Inputs!$B$12+20*LOG10($A26*1000) -> 101.0206
A27: =A9 -> 3 | B27: =Inputs!$B$12+20*LOG10($A27*1000) -> 104.54243
A28: =A10 -> 5 | B28: =Inputs!$B$12+20*LOG10($A28*1000) -> 108.9794
A29: =A11 -> 10 | B29: =Inputs!$B$12+20*LOG10($A29*1000) -> 115

Sheet Results
A1: Results per class and character
A2: Margins: positive passes, negative fails. Empty blocks: the class has no level entered.
A4: ="Class: "&Inputs!A24&" Character: "&Inputs!A31 -> Class: Small PA Character: Balanced
A5: Level at receptor (dB, octave band, unweighted)
A6: Distance (km) | B6: 31.5 Hz | C6: 63 Hz | D6: 125 Hz | E6: 250 Hz | F6: 500 Hz | G6: 1 kHz | H6: 2 kHz | I6: 4 kHz | J6: 8 kHz | K6: dB(A) | L6: dB(C) | M6: Margin to night target, dB(A) | N6: Under night target?
A7: =Inputs!$A$15 -> 0.5 | B7: =IF(OR(Inputs!$B$24="",Inputs!$C$24=""),"",Inputs!B$31+Inputs!$B$24-Inputs!$K$31-20*LOG10($A7*1000/Inputs!$C$24)-Reference!B$10*($A7*1000-Inputs!$C$24)/1000) -> 66.004987 | C7: =IF(OR(Inputs!$B$24="",Inputs!$C$24=""),"",Inputs!C$31+Inputs!$B$24-Inputs!$K$31-20*LOG10($A7*1000/Inputs!$C$24)-Reference!C$10*($A7*1000-Inputs!$C$24)/1000) -> 75.961053 | D7: =IF(OR(Inputs!$B$24="",Inputs!$C$24=""),"",Inputs!D$31+Inputs!$B$24-Inputs!$K$31-20*LOG10($A7*1000/Inputs!$C$24)-Reference!D$10*($A7*1000-Inputs!$C$24)/1000) -> 66.819315 | E7: =IF(OR(Inputs!$B$24="",Inputs!$C$24=""),"",Inputs!E$31+Inputs!$B$24-Inputs!$K$31-20*LOG10($A7*1000/Inputs!$C$24)-Reference!E$10*($A7*1000-Inputs!$C$24)/1000) -> 63.509431 | F7: =IF(OR(Inputs!$B$24="",Inputs!$C$24=""),"",Inputs!F$31+Inputs!$B$24-Inputs!$K$31-20*LOG10($A7*1000/Inputs!$C$24)-Reference!F$10*($A7*1000-Inputs!$C$24)/1000) -> 63.076029 | G7: =IF(OR(Inputs!$B$24="",Inputs!$C$24=""),"",Inputs!G$31+Inputs!$B$24-Inputs!$K$31-20*LOG10($A7*1000/Inputs!$C$24)-Reference!G$10*($A7*1000-Inputs!$C$24)/1000) -> 57.228415 | H7: =IF(OR(Inputs!$B$24="",Inputs!$C$24=""),"",Inputs!H$31+Inputs!$B$24-Inputs!$K$31-20*LOG10($A7*1000/Inputs!$C$24)-Reference!H$10*($A7*1000-Inputs!$C$24)/1000) -> 50.285348 | I7: =IF(OR(Inputs!$B$24="",Inputs!$C$24=""),"",Inputs!I$31+Inputs!$B$24-Inputs!$K$31-20*LOG10($A7*1000/Inputs!$C$24)-Reference!I$10*($A7*1000-Inputs!$C$24)/1000) -> 34.963318 | J7: =IF(OR(Inputs!$B$24="",Inputs!$C$24=""),"",Inputs!J$31+Inputs!$B$24-Inputs!$K$31-20*LOG10($A7*1000/Inputs!$C$24)-Reference!J$10*($A7*1000-Inputs!$C$24)/1000) -> -12.251521 | K7: =IF(COUNT(B7:J7)<9,"",10*LOG10(SUMPRODUCT(10^((B7:J7+Reference!$B$7:$J$7)/10)))) -> 63.359902 | L7: =IF(COUNT(B7:J7)<9,"",10*LOG10(SUMPRODUCT(10^((B7:J7+Reference!$B$8:$J$8)/10)))) -> 76.465334 | M7: =IF(ISNUMBER(K7),Inputs!$B$12-K7,"") -> -28.359902 | N7: =IF(ISNUMBER(M7),IF(M7>=0,"yes","no"),"") -> no
A8: =Inputs!$A$16 -> 1 | B8: =IF(OR(Inputs!$B$24="",Inputs!$C$24=""),"",Inputs!B$31+Inputs!$B$24-Inputs!$K$31-20*LOG10($A8*1000/Inputs!$C$24)-Reference!B$10*($A8*1000-Inputs!$C$24)/1000) -> 59.968372 | C8: =IF(OR(Inputs!$B$24="",Inputs!$C$24=""),"",Inputs!C$31+Inputs!$B$24-Inputs!$K$31-20*LOG10($A8*1000/Inputs!$C$24)-Reference!C$10*($A8*1000-Inputs!$C$24)/1000) -> 69.879609 | D8: =IF(OR(Inputs!$B$24="",Inputs!$C$24=""),"",Inputs!D$31+Inputs!$B$24-Inputs!$K$31-20*LOG10($A8*1000/Inputs!$C$24)-Reference!D$10*($A8*1000-Inputs!$C$24)/1000) -> 60.59324 | E8: =IF(OR(Inputs!$B$24="",Inputs!$C$24=""),"",Inputs!E$31+Inputs!$B$24-Inputs!$K$31-20*LOG10($A8*1000/Inputs!$C$24)-Reference!E$10*($A8*1000-Inputs!$C$24)/1000) -> 56.967148 | F8: =IF(OR(Inputs!$B$24="",Inputs!$C$24=""),"",Inputs!F$31+Inputs!$B$24-Inputs!$K$31-20*LOG10($A8*1000/Inputs!$C$24)-Reference!F$10*($A8*1000-Inputs!$C$24)/1000) -> 56.091498 | G8: =IF(OR(Inputs!$B$24="",Inputs!$C$24=""),"",Inputs!G$31+Inputs!$B$24-Inputs!$K$31-20*LOG10($A8*1000/Inputs!$C$24)-Reference!G$10*($A8*1000-Inputs!$C$24)/1000) -> 49.378972 | H8: =IF(OR(Inputs!$B$24="",Inputs!$C$24=""),"",Inputs!H$31+Inputs!$B$24-Inputs!$K$31-20*LOG10($A8*1000/Inputs!$C$24)-Reference!H$10*($A8*1000-Inputs!$C$24)/1000) -> 39.432775 | I8: =IF(OR(Inputs!$B$24="",Inputs!$C$24=""),"",Inputs!I$31+Inputs!$B$24-Inputs!$K$31-20*LOG10($A8*1000/Inputs!$C$24)-Reference!I$10*($A8*1000-Inputs!$C$24)/1000) -> 12.557653 | J8: =IF(OR(Inputs!$B$24="",Inputs!$C$24=""),"",Inputs!J$31+Inputs!$B$24-Inputs!$K$31-20*LOG10($A8*1000/Inputs!$C$24)-Reference!J$10*($A8*1000-Inputs!$C$24)/1000) -> -76.713143 | K8: =IF(COUNT(B8:J8)<9,"",10*LOG10(SUMPRODUCT(10^((B8:J8+Reference!$B$7:$J$7)/10)))) -> 56.160743 | L8: =IF(COUNT(B8:J8)<9,"",10*LOG10(SUMPRODUCT(10^((B8:J8+Reference!$B$8:$J$8)/10)))) -> 70.286371 | M8: =IF(ISNUMBER(K8),Inputs!$B$12-K8,"") -> -21.160743 | N8: =IF(ISNUMBER(M8),IF(M8>=0,"yes","no"),"") -> no
A9: =Inputs!$A$17 -> 2 | B9: =IF(OR(Inputs!$B$24="",Inputs!$C$24=""),"",Inputs!B$31+Inputs!$B$24-Inputs!$K$31-20*LOG10($A9*1000/Inputs!$C$24)-Reference!B$10*($A9*1000-Inputs!$C$24)/1000) -> 53.915744 | C9: =IF(OR(Inputs!$B$24="",Inputs!$C$24=""),"",Inputs!C$31+Inputs!$B$24-Inputs!$K$31-20*LOG10($A9*1000/Inputs!$C$24)-Reference!C$10*($A9*1000-Inputs!$C$24)/1000) -> 63.737319 | D9: =IF(OR(Inputs!$B$24="",Inputs!$C$24=""),"",Inputs!D$31+Inputs!$B$24-Inputs!$K$31-20*LOG10($A9*1000/Inputs!$C$24)-Reference!D$10*($A9*1000-Inputs!$C$24)/1000) -> 54.16169 | E9: =IF(OR(Inputs!$B$24="",Inputs!$C$24=""),"",Inputs!E$31+Inputs!$B$24-Inputs!$K$31-20*LOG10($A9*1000/Inputs!$C$24)-Reference!E$10*($A9*1000-Inputs!$C$24)/1000) -> 49.90318 | F9: =IF(OR(Inputs!$B$24="",Inputs!$C$24=""),"",Inputs!F$31+Inputs!$B$24-Inputs!$K$31-20*LOG10($A9*1000/Inputs!$C$24)-Reference!F$10*($A9*1000-Inputs!$C$24)/1000) -> 48.143036 | G9: =IF(OR(Inputs!$B$24="",Inputs!$C$24=""),"",Inputs!G$31+Inputs!$B$24-Inputs!$K$31-20*LOG10($A9*1000/Inputs!$C$24)-Reference!G$10*($A9*1000-Inputs!$C$24)/1000) -> 39.700687 | H9: =IF(OR(Inputs!$B$24="",Inputs!$C$24=""),"",Inputs!H$31+Inputs!$B$24-Inputs!$K$31-20*LOG10($A9*1000/Inputs!$C$24)-Reference!H$10*($A9*1000-Inputs!$C$24)/1000) -> 23.74823 | I9: =IF(OR(Inputs!$B$24="",Inputs!$C$24=""),"",Inputs!I$31+Inputs!$B$24-Inputs!$K$31-20*LOG10($A9*1000/Inputs!$C$24)-Reference!I$10*($A9*1000-Inputs!$C$24)/1000) -> -26.233077 | J9: =IF(OR(Inputs!$B$24="",Inputs!$C$24=""),"",Inputs!J$31+Inputs!$B$24-Inputs!$K$31-20*LOG10($A9*1000/Inputs!$C$24)-Reference!J$10*($A9*1000-Inputs!$C$24)/1000) -> -199.61579 | K9: =IF(COUNT(B9:J9)<9,"",10*LOG10(SUMPRODUCT(10^((B9:J9+Reference!$B$7:$J$7)/10)))) -> 48.225393 | L9: =IF(COUNT(B9:J9)<9,"",10*LOG10(SUMPRODUCT(10^((B9:J9+Reference!$B$8:$J$8)/10)))) -> 63.999665 | M9: =IF(ISNUMBER(K9),Inputs!$B$12-K9,"") -> -13.225393 | N9: =IF(ISNUMBER(M9),IF(M9>=0,"yes","no"),"") -> no
A10: =Inputs!$A$18 -> 3 | B10: =IF(OR(Inputs!$B$24="",Inputs!$C$24=""),"",Inputs!B$31+Inputs!$B$24-Inputs!$K$31-20*LOG10($A10*1000/Inputs!$C$24)-Reference!B$10*($A10*1000-Inputs!$C$24)/1000) -> 50.361889 | C10: =IF(OR(Inputs!$B$24="",Inputs!$C$24=""),"",Inputs!C$31+Inputs!$B$24-Inputs!$K$31-20*LOG10($A10*1000/Inputs!$C$24)-Reference!C$10*($A10*1000-Inputs!$C$24)/1000) -> 60.093805 | D10: =IF(OR(Inputs!$B$24="",Inputs!$C$24=""),"",Inputs!D$31+Inputs!$B$24-Inputs!$K$31-20*LOG10($A10*1000/Inputs!$C$24)-Reference!D$10*($A10*1000-Inputs!$C$24)/1000) -> 50.228915 | E10: =IF(OR(Inputs!$B$24="",Inputs!$C$24=""),"",Inputs!E$31+Inputs!$B$24-Inputs!$K$31-20*LOG10($A10*1000/Inputs!$C$24)-Reference!E$10*($A10*1000-Inputs!$C$24)/1000) -> 45.337988 | F10: =IF(OR(Inputs!$B$24="",Inputs!$C$24=""),"",Inputs!F$31+Inputs!$B$24-Inputs!$K$31-20*LOG10($A10*1000/Inputs!$C$24)-Reference!F$10*($A10*1000-Inputs!$C$24)/1000) -> 42.693348 | G10: =IF(OR(Inputs!$B$24="",Inputs!$C$24=""),"",Inputs!G$31+Inputs!$B$24-Inputs!$K$31-20*LOG10($A10*1000/Inputs!$C$24)-Reference!G$10*($A10*1000-Inputs!$C$24)/1000) -> 32.521176 | H10: =IF(OR(Inputs!$B$24="",Inputs!$C$24=""),"",Inputs!H$31+Inputs!$B$24-Inputs!$K$31-20*LOG10($A10*1000/Inputs!$C$24)-Reference!H$10*($A10*1000-Inputs!$C$24)/1000) -> 10.562459 | I10: =IF(OR(Inputs!$B$24="",Inputs!$C$24=""),"",Inputs!I$31+Inputs!$B$24-Inputs!$K$31-20*LOG10($A10*1000/Inputs!$C$24)-Reference!I$10*($A10*1000-Inputs!$C$24)/1000) -> -62.525031 | J10: =IF(OR(Inputs!$B$24="",Inputs!$C$24=""),"",Inputs!J$31+Inputs!$B$24-Inputs!$K$31-20*LOG10($A10*1000/Inputs!$C$24)-Reference!J$10*($A10*1000-Inputs!$C$24)/1000) -> -320.01966 | K10: =IF(COUNT(B10:J10)<9,"",10*LOG10(SUMPRODUCT(10^((B10:J10+Reference!$B$7:$J$7)/10)))) -> 43.111294 | L10: =IF(COUNT(B10:J10)<9,"",10*LOG10(SUMPRODUCT(10^((B10:J10+Reference!$B$8:$J$8)/10)))) -> 60.25158 | M10: =IF(ISNUMBER(K10),Inputs!$B$12-K10,"") -> -8.1112941 | N10: =IF(ISNUMBER(M10),IF(M10>=0,"yes","no"),"") -> no
A11: =Inputs!$A$19 -> 5 | B11: =IF(OR(Inputs!$B$24="",Inputs!$C$24=""),"",Inputs!B$31+Inputs!$B$24-Inputs!$K$31-20*LOG10($A11*1000/Inputs!$C$24)-Reference!B$10*($A11*1000-Inputs!$C$24)/1000) -> 45.860856 | C11: =IF(OR(Inputs!$B$24="",Inputs!$C$24=""),"",Inputs!C$31+Inputs!$B$24-Inputs!$K$31-20*LOG10($A11*1000/Inputs!$C$24)-Reference!C$10*($A11*1000-Inputs!$C$24)/1000) -> 55.413451 | D11: =IF(OR(Inputs!$B$24="",Inputs!$C$24=""),"",Inputs!D$31+Inputs!$B$24-Inputs!$K$31-20*LOG10($A11*1000/Inputs!$C$24)-Reference!D$10*($A11*1000-Inputs!$C$24)/1000) -> 44.970039 | E11: =IF(OR(Inputs!$B$24="",Inputs!$C$24=""),"",Inputs!E$31+Inputs!$B$24-Inputs!$K$31-20*LOG10($A11*1000/Inputs!$C$24)-Reference!E$10*($A11*1000-Inputs!$C$24)/1000) -> 38.814278 | F11: =IF(OR(Inputs!$B$24="",Inputs!$C$24=""),"",Inputs!F$31+Inputs!$B$24-Inputs!$K$31-20*LOG10($A11*1000/Inputs!$C$24)-Reference!F$10*($A11*1000-Inputs!$C$24)/1000) -> 34.400649 | G11: =IF(OR(Inputs!$B$24="",Inputs!$C$24=""),"",Inputs!G$31+Inputs!$B$24-Inputs!$K$31-20*LOG10($A11*1000/Inputs!$C$24)-Reference!G$10*($A11*1000-Inputs!$C$24)/1000) -> 20.768829 | H11: =IF(OR(Inputs!$B$24="",Inputs!$C$24=""),"",Inputs!H$31+Inputs!$B$24-Inputs!$K$31-20*LOG10($A11*1000/Inputs!$C$24)-Reference!H$10*($A11*1000-Inputs!$C$24)/1000) -> -13.202406 | I11: =IF(OR(Inputs!$B$24="",Inputs!$C$24=""),"",Inputs!I$31+Inputs!$B$24-Inputs!$K$31-20*LOG10($A11*1000/Inputs!$C$24)-Reference!I$10*($A11*1000-Inputs!$C$24)/1000) -> -132.50227 | J11: =IF(OR(Inputs!$B$24="",Inputs!$C$24=""),"",Inputs!J$31+Inputs!$B$24-Inputs!$K$31-20*LOG10($A11*1000/Inputs!$C$24)-Reference!J$10*($A11*1000-Inputs!$C$24)/1000) -> -558.22072 | K11: =IF(COUNT(B11:J11)<9,"",10*LOG10(SUMPRODUCT(10^((B11:J11+Reference!$B$7:$J$7)/10)))) -> 36.125869 | L11: =IF(COUNT(B11:J11)<9,"",10*LOG10(SUMPRODUCT(10^((B11:J11+Reference!$B$8:$J$8)/10)))) -> 55.429473 | M11: =IF(ISNUMBER(K11),Inputs!$B$12-K11,"") -> -1.1258694 | N11: =IF(ISNUMBER(M11),IF(M11>=0,"yes","no"),"") -> no
A12: =Inputs!$A$20 -> 10 | B12: =IF(OR(Inputs!$B$24="",Inputs!$C$24=""),"",Inputs!B$31+Inputs!$B$24-Inputs!$K$31-20*LOG10($A12*1000/Inputs!$C$24)-Reference!B$10*($A12*1000-Inputs!$C$24)/1000) -> 39.680111 | C12: =IF(OR(Inputs!$B$24="",Inputs!$C$24=""),"",Inputs!C$31+Inputs!$B$24-Inputs!$K$31-20*LOG10($A12*1000/Inputs!$C$24)-Reference!C$10*($A12*1000-Inputs!$C$24)/1000) -> 48.784404 | D12: =IF(OR(Inputs!$B$24="",Inputs!$C$24=""),"",Inputs!D$31+Inputs!$B$24-Inputs!$K$31-20*LOG10($A12*1000/Inputs!$C$24)-Reference!D$10*($A12*1000-Inputs!$C$24)/1000) -> 36.894688 | E12: =IF(OR(Inputs!$B$24="",Inputs!$C$24=""),"",Inputs!E$31+Inputs!$B$24-Inputs!$K$31-20*LOG10($A12*1000/Inputs!$C$24)-Reference!E$10*($A12*1000-Inputs!$C$24)/1000) -> 27.576841 | F12: =IF(OR(Inputs!$B$24="",Inputs!$C$24=""),"",Inputs!F$31+Inputs!$B$24-Inputs!$K$31-20*LOG10($A12*1000/Inputs!$C$24)-Reference!F$10*($A12*1000-Inputs!$C$24)/1000) -> 18.740739 | G12: =IF(OR(Inputs!$B$24="",Inputs!$C$24=""),"",Inputs!G$31+Inputs!$B$24-Inputs!$K$31-20*LOG10($A12*1000/Inputs!$C$24)-Reference!G$10*($A12*1000-Inputs!$C$24)/1000) -> -3.5401992 | H12: =IF(OR(Inputs!$B$24="",Inputs!$C$24=""),"",Inputs!H$31+Inputs!$B$24-Inputs!$K$31-20*LOG10($A12*1000/Inputs!$C$24)-Reference!H$10*($A12*1000-Inputs!$C$24)/1000) -> -67.542733 | I12: =IF(OR(Inputs!$B$24="",Inputs!$C$24=""),"",Inputs!I$31+Inputs!$B$24-Inputs!$K$31-20*LOG10($A12*1000/Inputs!$C$24)-Reference!I$10*($A12*1000-Inputs!$C$24)/1000) -> -302.37351 | J12: =IF(OR(Inputs!$B$24="",Inputs!$C$24=""),"",Inputs!J$31+Inputs!$B$24-Inputs!$K$31-20*LOG10($A12*1000/Inputs!$C$24)-Reference!J$10*($A12*1000-Inputs!$C$24)/1000) -> -1148.6515 | K12: =IF(COUNT(B12:J12)<9,"",10*LOG10(SUMPRODUCT(10^((B12:J12+Reference!$B$7:$J$7)/10)))) -> 26.208983 | L12: =IF(COUNT(B12:J12)<9,"",10*LOG10(SUMPRODUCT(10^((B12:J12+Reference!$B$8:$J$8)/10)))) -> 48.623987 | M12: =IF(ISNUMBER(K12),Inputs!$B$12-K12,"") -> 8.7910166 | N12: =IF(ISNUMBER(M12),IF(M12>=0,"yes","no"),"") -> yes
A13: Margin to hearing threshold (dB, positive = below threshold)
A14: Distance (km) | B14: 31.5 Hz | C14: 63 Hz | D14: 125 Hz | E14: 250 Hz | F14: 500 Hz | G14: 1 kHz | H14: 2 kHz | I14: 4 kHz | J14: 8 kHz | K14: Worst band | L14: Inaudible in all bands?
A15: =A7 -> 0.5 | B15: =IF(ISNUMBER(B7),Reference!B$9-B7,"") -> -6.5049869 | C15: =IF(ISNUMBER(C7),Reference!C$9-C7,"") -> -38.461053 | D15: =IF(ISNUMBER(D7),Reference!D$9-D7,"") -> -44.719315 | E15: =IF(ISNUMBER(E7),Reference!E$9-E7,"") -> -52.109431 | F15: =IF(ISNUMBER(F7),Reference!F$9-F7,"") -> -58.676029 | G15: =IF(ISNUMBER(G7),Reference!G$9-G7,"") -> -54.828415 | H15: =IF(ISNUMBER(H7),Reference!H$9-H7,"") -> -51.585348 | I15: =IF(ISNUMBER(I7),Reference!I$9-I7,"") -> -40.363318 | J15: =IF(ISNUMBER(J7),Reference!J$9-J7,"") -> 24.851521 | K15: =IF(COUNT(B15:J15)=0,"",MIN(B15:J15)) -> -58.676029 | L15: =IF(COUNT(B15:J15)<9,"",IF(K15>=0,"yes","no")) -> no
A16: =A8 -> 1 | B16: =IF(ISNUMBER(B8),Reference!B$9-B8,"") -> -0.46837249 | C16: =IF(ISNUMBER(C8),Reference!C$9-C8,"") -> -32.379609 | D16: =IF(ISNUMBER(D8),Reference!D$9-D8,"") -> -38.49324 | E16: =IF(ISNUMBER(E8),Reference!E$9-E8,"") -> -45.567148 | F16: =IF(ISNUMBER(F8),Reference!F$9-F8,"") -> -51.691498 | G16: =IF(ISNUMBER(G8),Reference!G$9-G8,"") -> -46.978972 | H16: =IF(ISNUMBER(H8),Reference!H$9-H8,"") -> -40.732775 | I16: =IF(ISNUMBER(I8),Reference!I$9-I8,"") -> -17.957653 | J16: =IF(ISNUMBER(J8),Reference!J$9-J8,"") -> 89.313143 | K16: =IF(COUNT(B16:J16)=0,"",MIN(B16:J16)) -> -51.691498 | L16: =IF(COUNT(B16:J16)<9,"",IF(K16>=0,"yes","no")) -> no
A17: =A9 -> 2 | B17: =IF(ISNUMBER(B9),Reference!B$9-B9,"") -> 5.5842564 | C17: =IF(ISNUMBER(C9),Reference!C$9-C9,"") -> -26.237319 | D17: =IF(ISNUMBER(D9),Reference!D$9-D9,"") -> -32.06169 | E17: =IF(ISNUMBER(E9),Reference!E$9-E9,"") -> -38.50318 | F17: =IF(ISNUMBER(F9),Reference!F$9-F9,"") -> -43.743036 | G17: =IF(ISNUMBER(G9),Reference!G$9-G9,"") -> -37.300687 | H17: =IF(ISNUMBER(H9),Reference!H$9-H9,"") -> -25.04823 | I17: =IF(ISNUMBER(I9),Reference!I$9-I9,"") -> 20.833077 | J17: =IF(ISNUMBER(J9),Reference!J$9-J9,"") -> 212.21579 | K17: =IF(COUNT(B17:J17)=0,"",MIN(B17:J17)) -> -43.743036 | L17: =IF(COUNT(B17:J17)<9,"",IF(K17>=0,"yes","no")) -> no
A18: =A10 -> 3 | B18: =IF(ISNUMBER(B10),Reference!B$9-B10,"") -> 9.1381106 | C18: =IF(ISNUMBER(C10),Reference!C$9-C10,"") -> -22.593805 | D18: =IF(ISNUMBER(D10),Reference!D$9-D10,"") -> -28.128915 | E18: =IF(ISNUMBER(E10),Reference!E$9-E10,"") -> -33.937988 | F18: =IF(ISNUMBER(F10),Reference!F$9-F10,"") -> -38.293348 | G18: =IF(ISNUMBER(G10),Reference!G$9-G10,"") -> -30.121176 | H18: =IF(ISNUMBER(H10),Reference!H$9-H10,"") -> -11.862459 | I18: =IF(ISNUMBER(I10),Reference!I$9-I10,"") -> 57.125031 | J18: =IF(ISNUMBER(J10),Reference!J$9-J10,"") -> 332.61966 | K18: =IF(COUNT(B18:J18)=0,"",MIN(B18:J18)) -> -38.293348 | L18: =IF(COUNT(B18:J18)<9,"",IF(K18>=0,"yes","no")) -> no
A19: =A11 -> 5 | B19: =IF(ISNUMBER(B11),Reference!B$9-B11,"") -> 13.639144 | C19: =IF(ISNUMBER(C11),Reference!C$9-C11,"") -> -17.913451 | D19: =IF(ISNUMBER(D11),Reference!D$9-D11,"") -> -22.870039 | E19: =IF(ISNUMBER(E11),Reference!E$9-E11,"") -> -27.414278 | F19: =IF(ISNUMBER(F11),Reference!F$9-F11,"") -> -30.000649 | G19: =IF(ISNUMBER(G11),Reference!G$9-G11,"") -> -18.368829 | H19: =IF(ISNUMBER(H11),Reference!H$9-H11,"") -> 11.902406 | I19: =IF(ISNUMBER(I11),Reference!I$9-I11,"") -> 127.10227 | J19: =IF(ISNUMBER(J11),Reference!J$9-J11,"") -> 570.82072 | K19: =IF(COUNT(B19:J19)=0,"",MIN(B19:J19)) -> -30.000649 | L19: =IF(COUNT(B19:J19)<9,"",IF(K19>=0,"yes","no")) -> no
A20: =A12 -> 10 | B20: =IF(ISNUMBER(B12),Reference!B$9-B12,"") -> 19.819889 | C20: =IF(ISNUMBER(C12),Reference!C$9-C12,"") -> -11.284404 | D20: =IF(ISNUMBER(D12),Reference!D$9-D12,"") -> -14.794688 | E20: =IF(ISNUMBER(E12),Reference!E$9-E12,"") -> -16.176841 | F20: =IF(ISNUMBER(F12),Reference!F$9-F12,"") -> -14.340739 | G20: =IF(ISNUMBER(G12),Reference!G$9-G12,"") -> 5.9401992 | H20: =IF(ISNUMBER(H12),Reference!H$9-H12,"") -> 66.242733 | I20: =IF(ISNUMBER(I12),Reference!I$9-I12,"") -> 296.97351 | J20: =IF(ISNUMBER(J12),Reference!J$9-J12,"") -> 1161.2515 | K20: =IF(COUNT(B20:J20)=0,"",MIN(B20:J20)) -> -16.176841 | L20: =IF(COUNT(B20:J20)<9,"",IF(K20>=0,"yes","no")) -> no
A22: ="Class: "&Inputs!A24&" Character: "&Inputs!A32 -> Class: Small PA Character: Bass heavy
A23: Level at receptor (dB, octave band, unweighted)
A24: Distance (km) | B24: 31.5 Hz | C24: 63 Hz | D24: 125 Hz | E24: 250 Hz | F24: 500 Hz | G24: 1 kHz | H24: 2 kHz | I24: 4 kHz | J24: 8 kHz | K24: dB(A) | L24: dB(C) | M24: Margin to night target, dB(A) | N24: Under night target?
A25: =Inputs!$A$15 -> 0.5 | B25: =IF(OR(Inputs!$B$24="",Inputs!$C$24=""),"",Inputs!B$32+Inputs!$B$24-Inputs!$K$32-20*LOG10($A25*1000/Inputs!$C$24)-Reference!B$10*($A25*1000-Inputs!$C$24)/1000) -> 75.603373 | C25: =IF(OR(Inputs!$B$24="",Inputs!$C$24=""),"",Inputs!C$32+Inputs!$B$24-Inputs!$K$32-20*LOG10($A25*1000/Inputs!$C$24)-Reference!C$10*($A25*1000-Inputs!$C$24)/1000) -> 79.559439 | D25: =IF(OR(Inputs!$B$24="",Inputs!$C$24=""),"",Inputs!D$32+Inputs!$B$24-Inputs!$K$32-20*LOG10($A25*1000/Inputs!$C$24)-Reference!D$10*($A25*1000-Inputs!$C$24)/1000) -> 64.417701 | E25: =IF(OR(Inputs!$B$24="",Inputs!$C$24=""),"",Inputs!E$32+Inputs!$B$24-Inputs!$K$32-20*LOG10($A25*1000/Inputs!$C$24)-Reference!E$10*($A25*1000-Inputs!$C$24)/1000) -> 62.107817 | F25: =IF(OR(Inputs!$B$24="",Inputs!$C$24=""),"",Inputs!F$32+Inputs!$B$24-Inputs!$K$32-20*LOG10($A25*1000/Inputs!$C$24)-Reference!F$10*($A25*1000-Inputs!$C$24)/1000) -> 59.674415 | G25: =IF(OR(Inputs!$B$24="",Inputs!$C$24=""),"",Inputs!G$32+Inputs!$B$24-Inputs!$K$32-20*LOG10($A25*1000/Inputs!$C$24)-Reference!G$10*($A25*1000-Inputs!$C$24)/1000) -> 58.826801 | H25: =IF(OR(Inputs!$B$24="",Inputs!$C$24=""),"",Inputs!H$32+Inputs!$B$24-Inputs!$K$32-20*LOG10($A25*1000/Inputs!$C$24)-Reference!H$10*($A25*1000-Inputs!$C$24)/1000) -> 51.883734 | I25: =IF(OR(Inputs!$B$24="",Inputs!$C$24=""),"",Inputs!I$32+Inputs!$B$24-Inputs!$K$32-20*LOG10($A25*1000/Inputs!$C$24)-Reference!I$10*($A25*1000-Inputs!$C$24)/1000) -> 36.561704 | J25: =IF(OR(Inputs!$B$24="",Inputs!$C$24=""),"",Inputs!J$32+Inputs!$B$24-Inputs!$K$32-20*LOG10($A25*1000/Inputs!$C$24)-Reference!J$10*($A25*1000-Inputs!$C$24)/1000) -> -6.6531348 | K25: =IF(COUNT(B25:J25)<9,"",10*LOG10(SUMPRODUCT(10^((B25:J25+Reference!$B$7:$J$7)/10)))) -> 62.854497 | L25: =IF(COUNT(B25:J25)<9,"",10*LOG10(SUMPRODUCT(10^((B25:J25+Reference!$B$8:$J$8)/10)))) -> 79.976993 | M25: =IF(ISNUMBER(K25),Inputs!$B$12-K25,"") -> -27.854497 | N25: =IF(ISNUMBER(M25),IF(M25>=0,"yes","no"),"") -> no
A26: =Inputs!$A$16 -> 1 | B26: =IF(OR(Inputs!$B$24="",Inputs!$C$24=""),"",Inputs!B$32+Inputs!$B$24-Inputs!$K$32-20*LOG10($A26*1000/Inputs!$C$24)-Reference!B$10*($A26*1000-Inputs!$C$24)/1000) -> 69.566758 | C26: =IF(OR(Inputs!$B$24="",Inputs!$C$24=""),"",Inputs!C$32+Inputs!$B$24-Inputs!$K$32-20*LOG10($A26*1000/Inputs!$C$24)-Reference!C$10*($A26*1000-Inputs!$C$24)/1000) -> 73.477995 | D26: =IF(OR(Inputs!$B$24="",Inputs!$C$24=""),"",Inputs!D$32+Inputs!$B$24-Inputs!$K$32-20*LOG10($A26*1000/Inputs!$C$24)-Reference!D$10*($A26*1000-Inputs!$C$24)/1000) -> 58.191626 | E26: =IF(OR(Inputs!$B$24="",Inputs!$C$24=""),"",Inputs!E$32+Inputs!$B$24-Inputs!$K$32-20*LOG10($A26*1000/Inputs!$C$24)-Reference!E$10*($A26*1000-Inputs!$C$24)/1000) -> 55.565533 | F26: =IF(OR(Inputs!$B$24="",Inputs!$C$24=""),"",Inputs!F$32+Inputs!$B$24-Inputs!$K$32-20*LOG10($A26*1000/Inputs!$C$24)-Reference!F$10*($A26*1000-Inputs!$C$24)/1000) -> 52.689884 | G26: =IF(OR(Inputs!$B$24="",Inputs!$C$24=""),"",Inputs!G$32+Inputs!$B$24-Inputs!$K$32-20*LOG10($A26*1000/Inputs!$C$24)-Reference!G$10*($A26*1000-Inputs!$C$24)/1000) -> 50.977358 | H26: =IF(OR(Inputs!$B$24="",Inputs!$C$24=""),"",Inputs!H$32+Inputs!$B$24-Inputs!$K$32-20*LOG10($A26*1000/Inputs!$C$24)-Reference!H$10*($A26*1000-Inputs!$C$24)/1000) -> 41.031161 | I26: =IF(OR(Inputs!$B$24="",Inputs!$C$24=""),"",Inputs!I$32+Inputs!$B$24-Inputs!$K$32-20*LOG10($A26*1000/Inputs!$C$24)-Reference!I$10*($A26*1000-Inputs!$C$24)/1000) -> 14.156039 | J26: =IF(OR(Inputs!$B$24="",Inputs!$C$24=""),"",Inputs!J$32+Inputs!$B$24-Inputs!$K$32-20*LOG10($A26*1000/Inputs!$C$24)-Reference!J$10*($A26*1000-Inputs!$C$24)/1000) -> -71.114757 | K26: =IF(COUNT(B26:J26)<9,"",10*LOG10(SUMPRODUCT(10^((B26:J26+Reference!$B$7:$J$7)/10)))) -> 55.456585 | L26: =IF(COUNT(B26:J26)<9,"",10*LOG10(SUMPRODUCT(10^((B26:J26+Reference!$B$8:$J$8)/10)))) -> 73.869604 | M26: =IF(ISNUMBER(K26),Inputs!$B$12-K26,"") -> -20.456585 | N26: =IF(ISNUMBER(M26),IF(M26>=0,"yes","no"),"") -> no
A27: =Inputs!$A$17 -> 2 | B27: =IF(OR(Inputs!$B$24="",Inputs!$C$24=""),"",Inputs!B$32+Inputs!$B$24-Inputs!$K$32-20*LOG10($A27*1000/Inputs!$C$24)-Reference!B$10*($A27*1000-Inputs!$C$24)/1000) -> 63.514129 | C27: =IF(OR(Inputs!$B$24="",Inputs!$C$24=""),"",Inputs!C$32+Inputs!$B$24-Inputs!$K$32-20*LOG10($A27*1000/Inputs!$C$24)-Reference!C$10*($A27*1000-Inputs!$C$24)/1000) -> 67.335705 | D27: =IF(OR(Inputs!$B$24="",Inputs!$C$24=""),"",Inputs!D$32+Inputs!$B$24-Inputs!$K$32-20*LOG10($A27*1000/Inputs!$C$24)-Reference!D$10*($A27*1000-Inputs!$C$24)/1000) -> 51.760076 | E27: =IF(OR(Inputs!$B$24="",Inputs!$C$24=""),"",Inputs!E$32+Inputs!$B$24-Inputs!$K$32-20*LOG10($A27*1000/Inputs!$C$24)-Reference!E$10*($A27*1000-Inputs!$C$24)/1000) -> 48.501566 | F27: =IF(OR(Inputs!$B$24="",Inputs!$C$24=""),"",Inputs!F$32+Inputs!$B$24-Inputs!$K$32-20*LOG10($A27*1000/Inputs!$C$24)-Reference!F$10*($A27*1000-Inputs!$C$24)/1000) -> 44.741422 | G27: =IF(OR(Inputs!$B$24="",Inputs!$C$24=""),"",Inputs!G$32+Inputs!$B$24-Inputs!$K$32-20*LOG10($A27*1000/Inputs!$C$24)-Reference!G$10*($A27*1000-Inputs!$C$24)/1000) -> 41.299073 | H27: =IF(OR(Inputs!$B$24="",Inputs!$C$24=""),"",Inputs!H$32+Inputs!$B$24-Inputs!$K$32-20*LOG10($A27*1000/Inputs!$C$24)-Reference!H$10*($A27*1000-Inputs!$C$24)/1000) -> 25.346616 | I27: =IF(OR(Inputs!$B$24="",Inputs!$C$24=""),"",Inputs!I$32+Inputs!$B$24-Inputs!$K$32-20*LOG10($A27*1000/Inputs!$C$24)-Reference!I$10*($A27*1000-Inputs!$C$24)/1000) -> -24.634691 | J27: =IF(OR(Inputs!$B$24="",Inputs!$C$24=""),"",Inputs!J$32+Inputs!$B$24-Inputs!$K$32-20*LOG10($A27*1000/Inputs!$C$24)-Reference!J$10*($A27*1000-Inputs!$C$24)/1000) -> -194.0174 | K27: =IF(COUNT(B27:J27)<9,"",10*LOG10(SUMPRODUCT(10^((B27:J27+Reference!$B$7:$J$7)/10)))) -> 47.395959 | L27: =IF(COUNT(B27:J27)<9,"",10*LOG10(SUMPRODUCT(10^((B27:J27+Reference!$B$8:$J$8)/10)))) -> 67.698967 | M27: =IF(ISNUMBER(K27),Inputs!$B$12-K27,"") -> -12.395959 | N27: =IF(ISNUMBER(M27),IF(M27>=0,"yes","no"),"") -> no
A28: =Inputs!$A$18 -> 3 | B28: =IF(OR(Inputs!$B$24="",Inputs!$C$24=""),"",Inputs!B$32+Inputs!$B$24-Inputs!$K$32-20*LOG10($A28*1000/Inputs!$C$24)-Reference!B$10*($A28*1000-Inputs!$C$24)/1000) -> 59.960275 | C28: =IF(OR(Inputs!$B$24="",Inputs!$C$24=""),"",Inputs!C$32+Inputs!$B$24-Inputs!$K$32-20*LOG10($A28*1000/Inputs!$C$24)-Reference!C$10*($A28*1000-Inputs!$C$24)/1000) -> 63.692191 | D28: =IF(OR(Inputs!$B$24="",Inputs!$C$24=""),"",Inputs!D$32+Inputs!$B$24-Inputs!$K$32-20*LOG10($A28*1000/Inputs!$C$24)-Reference!D$10*($A28*1000-Inputs!$C$24)/1000) -> 47.827301 | E28: =IF(OR(Inputs!$B$24="",Inputs!$C$24=""),"",Inputs!E$32+Inputs!$B$24-Inputs!$K$32-20*LOG10($A28*1000/Inputs!$C$24)-Reference!E$10*($A28*1000-Inputs!$C$24)/1000) -> 43.936374 | F28: =IF(OR(Inputs!$B$24="",Inputs!$C$24=""),"",Inputs!F$32+Inputs!$B$24-Inputs!$K$32-20*LOG10($A28*1000/Inputs!$C$24)-Reference!F$10*($A28*1000-Inputs!$C$24)/1000) -> 39.291734 | G28: =IF(OR(Inputs!$B$24="",Inputs!$C$24=""),"",Inputs!G$32+Inputs!$B$24-Inputs!$K$32-20*LOG10($A28*1000/Inputs!$C$24)-Reference!G$10*($A28*1000-Inputs!$C$24)/1000) -> 34.119562 | H28: =IF(OR(Inputs!$B$24="",Inputs!$C$24=""),"",Inputs!H$32+Inputs!$B$24-Inputs!$K$32-20*LOG10($A28*1000/Inputs!$C$24)-Reference!H$10*($A28*1000-Inputs!$C$24)/1000) -> 12.160845 | I28: =IF(OR(Inputs!$B$24="",Inputs!$C$24=""),"",Inputs!I$32+Inputs!$B$24-Inputs!$K$32-20*LOG10($A28*1000/Inputs!$C$24)-Reference!I$10*($A28*1000-Inputs!$C$24)/1000) -> -60.926646 | J28: =IF(OR(Inputs!$B$24="",Inputs!$C$24=""),"",Inputs!J$32+Inputs!$B$24-Inputs!$K$32-20*LOG10($A28*1000/Inputs!$C$24)-Reference!J$10*($A28*1000-Inputs!$C$24)/1000) -> -314.42127 | K28: =IF(COUNT(B28:J28)<9,"",10*LOG10(SUMPRODUCT(10^((B28:J28+Reference!$B$7:$J$7)/10)))) -> 42.381012 | L28: =IF(COUNT(B28:J28)<9,"",10*LOG10(SUMPRODUCT(10^((B28:J28+Reference!$B$8:$J$8)/10)))) -> 64.042723 | M28: =IF(ISNUMBER(K28),Inputs!$B$12-K28,"") -> -7.3810117 | N28: =IF(ISNUMBER(M28),IF(M28>=0,"yes","no"),"") -> no
A29: =Inputs!$A$19 -> 5 | B29: =IF(OR(Inputs!$B$24="",Inputs!$C$24=""),"",Inputs!B$32+Inputs!$B$24-Inputs!$K$32-20*LOG10($A29*1000/Inputs!$C$24)-Reference!B$10*($A29*1000-Inputs!$C$24)/1000) -> 55.459242 | C29: =IF(OR(Inputs!$B$24="",Inputs!$C$24=""),"",Inputs!C$32+Inputs!$B$24-Inputs!$K$32-20*LOG10($A29*1000/Inputs!$C$24)-Reference!C$10*($A29*1000-Inputs!$C$24)/1000) -> 59.011837 | D29: =IF(OR(Inputs!$B$24="",Inputs!$C$24=""),"",Inputs!D$32+Inputs!$B$24-Inputs!$K$32-20*LOG10($A29*1000/Inputs!$C$24)-Reference!D$10*($A29*1000-Inputs!$C$24)/1000) -> 42.568425 | E29: =IF(OR(Inputs!$B$24="",Inputs!$C$24=""),"",Inputs!E$32+Inputs!$B$24-Inputs!$K$32-20*LOG10($A29*1000/Inputs!$C$24)-Reference!E$10*($A29*1000-Inputs!$C$24)/1000) -> 37.412664 | F29: =IF(OR(Inputs!$B$24="",Inputs!$C$24=""),"",Inputs!F$32+Inputs!$B$24-Inputs!$K$32-20*LOG10($A29*1000/Inputs!$C$24)-Reference!F$10*($A29*1000-Inputs!$C$24)/1000) -> 30.999035 | G29: =IF(OR(Inputs!$B$24="",Inputs!$C$24=""),"",Inputs!G$32+Inputs!$B$24-Inputs!$K$32-20*LOG10($A29*1000/Inputs!$C$24)-Reference!G$10*($A29*1000-Inputs!$C$24)/1000) -> 22.367215 | H29: =IF(OR(Inputs!$B$24="",Inputs!$C$24=""),"",Inputs!H$32+Inputs!$B$24-Inputs!$K$32-20*LOG10($A29*1000/Inputs!$C$24)-Reference!H$10*($A29*1000-Inputs!$C$24)/1000) -> -11.60402 | I29: =IF(OR(Inputs!$B$24="",Inputs!$C$24=""),"",Inputs!I$32+Inputs!$B$24-Inputs!$K$32-20*LOG10($A29*1000/Inputs!$C$24)-Reference!I$10*($A29*1000-Inputs!$C$24)/1000) -> -130.90388 | J29: =IF(OR(Inputs!$B$24="",Inputs!$C$24=""),"",Inputs!J$32+Inputs!$B$24-Inputs!$K$32-20*LOG10($A29*1000/Inputs!$C$24)-Reference!J$10*($A29*1000-Inputs!$C$24)/1000) -> -552.62233 | K29: =IF(COUNT(B29:J29)<9,"",10*LOG10(SUMPRODUCT(10^((B29:J29+Reference!$B$7:$J$7)/10)))) -> 35.944201 | L29: =IF(COUNT(B29:J29)<9,"",10*LOG10(SUMPRODUCT(10^((B29:J29+Reference!$B$8:$J$8)/10)))) -> 59.359395 | M29: =IF(ISNUMBER(K29),Inputs!$B$12-K29,"") -> -0.94420105 | N29: =IF(ISNUMBER(M29),IF(M29>=0,"yes","no"),"") -> no
A30: =Inputs!$A$20 -> 10 | B30: =IF(OR(Inputs!$B$24="",Inputs!$C$24=""),"",Inputs!B$32+Inputs!$B$24-Inputs!$K$32-20*LOG10($A30*1000/Inputs!$C$24)-Reference!B$10*($A30*1000-Inputs!$C$24)/1000) -> 49.278497 | C30: =IF(OR(Inputs!$B$24="",Inputs!$C$24=""),"",Inputs!C$32+Inputs!$B$24-Inputs!$K$32-20*LOG10($A30*1000/Inputs!$C$24)-Reference!C$10*($A30*1000-Inputs!$C$24)/1000) -> 52.38279 | D30: =IF(OR(Inputs!$B$24="",Inputs!$C$24=""),"",Inputs!D$32+Inputs!$B$24-Inputs!$K$32-20*LOG10($A30*1000/Inputs!$C$24)-Reference!D$10*($A30*1000-Inputs!$C$24)/1000) -> 34.493074 | E30: =IF(OR(Inputs!$B$24="",Inputs!$C$24=""),"",Inputs!E$32+Inputs!$B$24-Inputs!$K$32-20*LOG10($A30*1000/Inputs!$C$24)-Reference!E$10*($A30*1000-Inputs!$C$24)/1000) -> 26.175227 | F30: =IF(OR(Inputs!$B$24="",Inputs!$C$24=""),"",Inputs!F$32+Inputs!$B$24-Inputs!$K$32-20*LOG10($A30*1000/Inputs!$C$24)-Reference!F$10*($A30*1000-Inputs!$C$24)/1000) -> 15.339125 | G30: =IF(OR(Inputs!$B$24="",Inputs!$C$24=""),"",Inputs!G$32+Inputs!$B$24-Inputs!$K$32-20*LOG10($A30*1000/Inputs!$C$24)-Reference!G$10*($A30*1000-Inputs!$C$24)/1000) -> -1.9418133 | H30: =IF(OR(Inputs!$B$24="",Inputs!$C$24=""),"",Inputs!H$32+Inputs!$B$24-Inputs!$K$32-20*LOG10($A30*1000/Inputs!$C$24)-Reference!H$10*($A30*1000-Inputs!$C$24)/1000) -> -65.944347 | I30: =IF(OR(Inputs!$B$24="",Inputs!$C$24=""),"",Inputs!I$32+Inputs!$B$24-Inputs!$K$32-20*LOG10($A30*1000/Inputs!$C$24)-Reference!I$10*($A30*1000-Inputs!$C$24)/1000) -> -300.77513 | J30: =IF(OR(Inputs!$B$24="",Inputs!$C$24=""),"",Inputs!J$32+Inputs!$B$24-Inputs!$K$32-20*LOG10($A30*1000/Inputs!$C$24)-Reference!J$10*($A30*1000-Inputs!$C$24)/1000) -> -1143.0532 | K30: =IF(COUNT(B30:J30)<9,"",10*LOG10(SUMPRODUCT(10^((B30:J30+Reference!$B$7:$J$7)/10)))) -> 27.545308 | L30: =IF(COUNT(B30:J30)<9,"",10*LOG10(SUMPRODUCT(10^((B30:J30+Reference!$B$8:$J$8)/10)))) -> 52.777379 | M30: =IF(ISNUMBER(K30),Inputs!$B$12-K30,"") -> 7.454692 | N30: =IF(ISNUMBER(M30),IF(M30>=0,"yes","no"),"") -> yes
A31: Margin to hearing threshold (dB, positive = below threshold)
A32: Distance (km) | B32: 31.5 Hz | C32: 63 Hz | D32: 125 Hz | E32: 250 Hz | F32: 500 Hz | G32: 1 kHz | H32: 2 kHz | I32: 4 kHz | J32: 8 kHz | K32: Worst band | L32: Inaudible in all bands?
A33: =A25 -> 0.5 | B33: =IF(ISNUMBER(B25),Reference!B$9-B25,"") -> -16.103373 | C33: =IF(ISNUMBER(C25),Reference!C$9-C25,"") -> -42.059439 | D33: =IF(ISNUMBER(D25),Reference!D$9-D25,"") -> -42.317701 | E33: =IF(ISNUMBER(E25),Reference!E$9-E25,"") -> -50.707817 | F33: =IF(ISNUMBER(F25),Reference!F$9-F25,"") -> -55.274415 | G33: =IF(ISNUMBER(G25),Reference!G$9-G25,"") -> -56.426801 | H33: =IF(ISNUMBER(H25),Reference!H$9-H25,"") -> -53.183734 | I33: =IF(ISNUMBER(I25),Reference!I$9-I25,"") -> -41.961704 | J33: =IF(ISNUMBER(J25),Reference!J$9-J25,"") -> 19.253135 | K33: =IF(COUNT(B33:J33)=0,"",MIN(B33:J33)) -> -56.426801 | L33: =IF(COUNT(B33:J33)<9,"",IF(K33>=0,"yes","no")) -> no
A34: =A26 -> 1 | B34: =IF(ISNUMBER(B26),Reference!B$9-B26,"") -> -10.066758 | C34: =IF(ISNUMBER(C26),Reference!C$9-C26,"") -> -35.977995 | D34: =IF(ISNUMBER(D26),Reference!D$9-D26,"") -> -36.091626 | E34: =IF(ISNUMBER(E26),Reference!E$9-E26,"") -> -44.165533 | F34: =IF(ISNUMBER(F26),Reference!F$9-F26,"") -> -48.289884 | G34: =IF(ISNUMBER(G26),Reference!G$9-G26,"") -> -48.577358 | H34: =IF(ISNUMBER(H26),Reference!H$9-H26,"") -> -42.331161 | I34: =IF(ISNUMBER(I26),Reference!I$9-I26,"") -> -19.556039 | J34: =IF(ISNUMBER(J26),Reference!J$9-J26,"") -> 83.714757 | K34: =IF(COUNT(B34:J34)=0,"",MIN(B34:J34)) -> -48.577358 | L34: =IF(COUNT(B34:J34)<9,"",IF(K34>=0,"yes","no")) -> no
A35: =A27 -> 2 | B35: =IF(ISNUMBER(B27),Reference!B$9-B27,"") -> -4.0141295 | C35: =IF(ISNUMBER(C27),Reference!C$9-C27,"") -> -29.835705 | D35: =IF(ISNUMBER(D27),Reference!D$9-D27,"") -> -29.660076 | E35: =IF(ISNUMBER(E27),Reference!E$9-E27,"") -> -37.101566 | F35: =IF(ISNUMBER(F27),Reference!F$9-F27,"") -> -40.341422 | G35: =IF(ISNUMBER(G27),Reference!G$9-G27,"") -> -38.899073 | H35: =IF(ISNUMBER(H27),Reference!H$9-H27,"") -> -26.646616 | I35: =IF(ISNUMBER(I27),Reference!I$9-I27,"") -> 19.234691 | J35: =IF(ISNUMBER(J27),Reference!J$9-J27,"") -> 206.6174 | K35: =IF(COUNT(B35:J35)=0,"",MIN(B35:J35)) -> -40.341422 | L35: =IF(COUNT(B35:J35)<9,"",IF(K35>=0,"yes","no")) -> no
